Workbook

Sheet Loom Link

Sheet Task 1 
A1: Post ID | B1: Platform | C1: Date | D1: Content Type | E1: Post Text | F1: Likes | G1: Shares | H1: Comments | I1: Impressions | J1: Reach | K1: Clicks | L1: Hashtags Used.2 | M1: Hashtags Used.3 | N1: Campaign_Name | O1: Start Date | P1: End date | Q1: Campaign Phase | R1: Sum Engagement | S1: Engagement Rate
A2: P220 | B2: Instagram | C2: 45445 | D2: Story | E2: Explore the latest story on Myntra! Trendy styles await. | F2: 84 | G2: 897 | H2: 85 | I2: 588 | J2: 8 | K2: 12 | L2: StyleWithMyntra | M2: NA | N2: EndOfSeasonSale | O2: =VLOOKUP(N2,'Campaign Data'!A:D,2,FALSE) -> 45453 | P2: =VLOOKUP(N2,'Campaign Data'!A:D,3,FALSE) -> 45478 | Q2: =IF(AND(C3>=O3,C3<=P3),"During Campaign","Before Campaign") -> Before Campaign | R2: =(Post[[#This Row],[Likes]]+Post[[#This Row],[Shares]]+Post[[#This Row],[Comments]]) -> 1066 | S2: =(Post[[#This Row],[Likes]]+Post[[#This Row],[Shares]]+Post[[#This Row],[Comments]]) / Post[[#This Row],[Impressions]] -> 1.8129252
A3: P058 | B3: Instagram | C3: 45762 | D3: Reel | E3: Explore the latest reel on Myntra! Trendy styles await. | F3: 103 | G3: 770 | H3: 19 | I3: 1030 | J3: 410 | K3: 262 | L3: MyntraSale | M3: NA | N3: MyntraFestiveEdit | O3: =VLOOKUP(N3,'Campaign Data'!A:D,2,FALSE) -> 45570 | P3: =VLOOKUP(N3,'Campaign Data'!A:D,3,FALSE) -> 45601 | Q3: =IF(AND(C4>=O4,C4<=P4),"During Campaign","Before Campaign") -> Before Campaign | R3: =(Post[[#This Row],[Likes]]+Post[[#This Row],[Shares]]+Post[[#This Row],[Comments]]) -> 892 | S3: =(Post[[#This Row],[Likes]]+Post[[#This Row],[Shares]]+Post[[#This Row],[Comments]]) / Post[[#This Row],[Impressions]] -> 0.86601942
A4: P232 | B4: Twitter | C4: 45776 | D4: Story | E4: Explore the latest story on Myntra! Trendy styles await. | F4: 249 | G4: 592 | H4: 230 | I4: 1494 | J4: 1044 | K4: 201 | L4: MyntraFashion | M4: MyntraTrend | N4: StyleRevolution | O4: =VLOOKUP(N4,'Campaign Data'!A:D,2,FALSE) -> 45667 | P4: =VLOOKUP(N4,'Campaign Data'!A:D,3,FALSE) -> 45698 | Q4: =IF(AND(C5>=O5,C5<=P5),"During Campaign","Before Campaign") -> Before Campaign | R4: =(Post[[#This Row],[Likes]]+Post[[#This Row],[Shares]]+Post[[#This Row],[Comments]]) -> 1071 | S4: =(Post[[#This Row],[Likes]]+Post[[#This Row],[Shares]]+Post[[#This Row],[Comments]]) / Post[[#This Row],[Impressions]] -> 0.71686747
A5: P178 | B5: Instagram | C5: 45603 | D5: Video | E5: Explore the latest video on Myntra! Trendy styles await. | F5: 129 | G5: 643 | H5: 136 | I5: 1290 | J5: 839 | K5: 238 | L5: StyleWithMyntra | M5: FashionDeals | N5: StyleRevolution | O5: =VLOOKUP(N5,'Campaign Data'!A:D,2,FALSE) -> 45667 | P5: =VLOOKUP(N5,'Campaign Data'!A:D,3,FALSE) -> 45698 | Q5: =IF(AND(C6>=O6,C6<=P6),"During Campaign","Before Campaign") -> Before Campaign | R5: =(Post[[#This Row],[Likes]]+Post[[#This Row],[Shares]]+Post[[#This Row],[Comments]]) -> 908 | S5: =(Post[[#This Row],[Likes]]+Post[[#This Row],[Shares]]+Post[[#This Row],[Comments]]) / Post[[#This Row],[Impressions]] -> 0.70387597
A6: P175 | B6: Instagram | C6: 45674 | D6: Reel | E6: Explore the latest reel on Myntra! Trendy styles await. | F6: 142 | G6: 784 | H6: 183 | I6: 1704 | J6: 995 | K6: 154 | L6: MyntraSale | M6: NA | N6: FashionUpgrade | O6: =VLOOKUP(N6,'Campaign Data'!A:D,2,FALSE) -> 45505 | P6: =VLOOKUP(N6,'Campaign Data'!A:D,3,FALSE) -> 45535 | Q6: =IF(AND(C7>=O7,C7<=P7),"During Campaign","Before Campaign") -> Before Campaign | R6: =(Post[[#This Row],[Likes]]+Post[[#This Row],[Shares]]+Post[[#This Row],[Comments]]) -> 1109 | S6: =(Post[[#This Row],[Likes]]+Post[[#This Row],[Shares]]+Post[[#This Row],[Comments]]) / Post[[#This Row],[Impressions]] -> 0.6508216
A7: P062 | B7: Twitter | C7: 45618 | D7: Carousel | E7: Explore the latest carousel on Myntra! Trendy styles await. | F7: 53 | G7: 81 | H7: 379 | I7: 954 | J7: 7 | K7: 148 | L7: FashionDeals | M7: NA | N7: MyntraFestiveEdit | O7: =VLOOKUP(N7,'Campaign Data'!A:D,2,FALSE) -> 45570 | P7: =VLOOKUP(N7,'Campaign Data'!A:D,3,FALSE) -> 45601 | Q7: =IF(AND(C8>=O8,C8<=P8),"During Campaign","Before Campaign") -> During Campaign | R7: =(Post[[#This Row],[Likes]]+Post[[#This Row],[Shares]]+Post[[#This Row],[Comments]]) -> 513 | S7: =(Post[[#This Row],[Likes]]+Post[[#This Row],[Shares]]+Post[[#This Row],[Comments]]) / Post[[#This Row],[Impressions]] -> 0.53773585
A8: P264 | B8: Twitter | C8: 45687 | D8: Image | E8: Explore the latest image on Myntra! Trendy styles await. | F8: 59 | G8: 163 | H8: 93 | I8: 590 | J8: 475 | K8: 293 | L8: MyntraTrend | M8: NA | N8: StyleRevolution | O8: =VLOOKUP(N8,'Campaign Data'!A:D,2,FALSE) -> 45667 | P8: =VLOOKUP(N8,'Campaign Data'!A:D,3,FALSE) -> 45698 | Q8: =IF(AND(C9>=O9,C9<=P9),"During Campaign","Before Campaign") -> Before Campaign | R8: =(Post[[#This Row],[Likes]]+Post[[#This Row],[Shares]]+Post[[#This Row],[Comments]]) -> 315 | S8: =(Post[[#This Row],[Likes]]+Post[[#This Row],[Shares]]+Post[[#This Row],[Comments]]) / Post[[#This Row],[Impressions]] -> 0.53389831
A9: P143 | B9: YouTube | C9: 45567 | D9: Carousel | E9: Explore the latest carousel on Myntra! Trendy styles await. | F9: 80 | G9: 362 | H9: 80 | I9: 1040 | J9: 349 | K9: 117 | L9: MyntraFashion | M9: StyleWithMyntra | N9: EndOfSeasonSale | O9: =VLOOKUP(N9,'Campaign Data'!A:D,2,FALSE) -> 45453 | P9: =VLOOKUP(N9,'Campaign Data'!A:D,3,FALSE) -> 45478 | Q9: =IF(AND(C10>=O10,C10<=P10),"During Campaign","Before Campaign") -> Before Campaign | R9: =(Post[[#This Row],[Likes]]+Post[[#This Row],[Shares]]+Post[[#This Row],[Comments]]) -> 522 | S9: =(Post[[#This Row],[Likes]]+Post[[#This Row],[Shares]]+Post[[#This Row],[Comments]]) / Post[[#This Row],[Impressions]] -> 0.50192308
A10: P210 | B10: YouTube | C10: 45707 | D10: Image | E10: Explore the latest image on Myntra! Trendy styles await. | F10: 257 | G10: 966 | H10: 398 | I10: 3341 | J10: 2753 | K10: 287 | L10: MyntraTrend | M10: MyntraSale | N10: FashionUpgrade | O10: =VLOOKUP(N10,'Campaign Data'!A:D,2,FALSE) -> 45505 | P10: =VLOOKUP(N10,'Campaign Data'!A:D,3,FALSE) -> 45535 | Q10: =IF(AND(C11>=O11,C11<=P11),"During Campaign","Before Campaign") -> Before Campaign | R10: =(Post[[#This Row],[Likes]]+Post[[#This Row],[Shares]]+Post[[#This Row],[Comments]]) -> 1621 | S10: =(Post[[#This Row],[Likes]]+Post[[#This Row],[Shares]]+Post[[#This Row],[Comments]]) / Post[[#This Row],[Impressions]] -> 0.48518408
A11: P070 | B11: Facebook | C11: 45749 | D11: Video | E11: Explore the latest video on Myntra! Trendy styles await. | F11: 199 | G11: 772 | H11: 400 | I11: 3582 | J11: 2988 | K11: 43 | L11: MyntraTrend | M11: NA | N11: FashionUpgrade | O11: =VLOOKUP(N11,'Campaign Data'!A:D,2,FALSE) -> 45505 | P11: =VLOOKUP(N11,'Campaign Data'!A:D,3,FALSE) -> 45535 | Q11: =IF(AND(C12>=O12,C12<=P12),"During Campaign","Before Campaign") -> Before Campaign | R11: =(Post[[#This Row],[Likes]]+Post[[#This Row],[Shares]]+Post[[#This Row],[Comments]]) -> 1371 | S11: =(Post[[#This Row],[Likes]]+Post[[#This Row],[Shares]]+Post[[#This Row],[Comments]]) / Post[[#This Row],[Impressions]] -> 0.38274707
A12: P214 | B12: Instagram | C12: 45649 | D12: Image | E12: Explore the latest image on Myntra! Trendy styles await. | F12: 521 | G12: 746 | H12: 315 | I12: 4168 | J12: 3399 | K12: 282 | L12: MyntraSale | M12: NA | N12: FashionUpgrade | O12: =VLOOKUP(N12,'Campaign Data'!A:D,2,FALSE) -> 45505 | P12: =VLOOKUP(N12,'Campaign Data'!A:D,3,FALSE) -> 45535 | Q12: =IF(AND(C13>=O13,C13<=P13),"During Campaign","Before Campaign") -> Before Campaign | R12: =(Post[[#This Row],[Likes]]+Post[[#This Row],[Shares]]+Post[[#This Row],[Comments]]) -> 1582 | S12: =(Post[[#This Row],[Likes]]+Post[[#This Row],[Shares]]+Post[[#This Row],[Comments]]) / Post[[#This Row],[Impressions]] -> 0.37955854
A13: P053 | B13: YouTube | C13: 45712 | D13: Carousel | E13: Explore the latest carousel on Myntra! Trendy styles await. | F13: 804 | G13: 639 | H13: 43 | I13: 4020 | J13: 3144 | K13: 11 | L13: StyleWithMyntra | M13: MyntraTrend | N13: StyleRevolution | O13: =VLOOKUP(N13,'Campaign Data'!A:D,2,FALSE) -> 45667 | P13: =VLOOKUP(N13,'Campaign Data'!A:D,3,FALSE) -> 45698 | Q13: =IF(AND(C14>=O14,C14<=P14),"During Campaign","Before Campaign") -> Before Campaign | R13: =(Post[[#This Row],[Likes]]+Post[[#This Row],[Shares]]+Post[[#This Row],[Comments]]) -> 1486 | S13: =(Post[[#This Row],[Likes]]+Post[[#This Row],[Shares]]+Post[[#This Row],[Comments]]) / Post[[#This Row],[Impressions]] -> 0.36965174
... A301: P063 | B301: Twitter | C301: 45504 | D301: Carousel | E301: Explore the latest carousel on Myntra! Trendy styles await. | F301: 4507 | G301: 217 | H301: 13 | I301: 90140 | J301: 89591 | K301: 125 | L301: MyntraSale | M301: NA | N301: FashionUpgrade | O301: =VLOOKUP(N301,'Campaign Data'!A:D,2,FALSE) -> 45505 | P301: =VLOOKUP(N301,'Campaign Data'!A:D,3,FALSE) -> 45535 | Q301: =IF(AND(C302>=O302,C302<=P302),"During Campaign","Before Campaign") -> During Campaign | R301: =(Post[[#This Row],[Likes]]+Post[[#This Row],[Shares]]+Post[[#This Row],[Comments]]) -> 4737 | S301: =(Post[[#This Row],[Likes]]+Post[[#This Row],[Shares]]+Post[[#This Row],[Comments]]) / Post[[#This Row],[Impressions]] -> 0.052551586

Sheet Task 2
A5: Task 2.1 | B5: Average Engagement Rate Per Platform
B6: Row Labels | C6: Average of Engagement Rate
B7: Facebook | C7: 0.1219729
B8: Instagram | C8: 0.19329258
B9: Twitter | C9: 0.14368407
B10: YouTube | C10: 0.13118494
B11: Grand Total | C11: 0.14828272
A15: Task 2.2 | B15: Top 10 Myntra posts with highest engagement.
B16: Post ID | C16: Date | D16: Content Type | E16: Engagement Rate
B17: P220 | C17: 45445 | D17: Story | E17: 1.8129252
B18: P058 | C18: 45762 | D18: Reel | E18: 0.86601942
B19: P232 | C19: 45776 | D19: Story | E19: 0.71686747
B20: P178 | C20: 45603 | D20: Video | E20: 0.70387597
B21: P175 | C21: 45674 | D21: Reel | E21: 0.6508216
B22: P062 | C22: 45618 | D22: Carousel | E22: 0.53773585
B23: P264 | C23: 45687 | D23: Image | E23: 0.53389831
B24: P143 | C24: 45567 | D24: Carousel | E24: 0.50192308
B25: P210 | C25: 45707 | D25: Image | E25: 0.48518408
B26: P070 | C26: 45749 | D26: Video | E26: 0.38274707
A31: Task 2.3 | B31: Total Likes, Shares, Comments by Content Type & Platform | K31: Task 2.3 | L31: Average Clicks per post by Hashtag
B33: Platfrom | C33: Total of Likes | D33: Total of Shares | E33: Total of Comments | K33: Row Labels | L33: Average of Clicks
B34: Facebook | C34: 242761 | D34: 39181 | E34: 23300 | K34: FashionDeals | L34: 159.76
B35: Carousel | C35: 44476 | D35: 7400 | E35: 4589 | K35: MyntraFashion | L35: 141.34545
B36: Image | C36: 71602 | D36: 12904 | E36: 6495 | K36: MyntraSale | L36: 145.92754
B37: Reel | C37: 36368 | D37: 5964 | E37: 3353 | K37: MyntraTrend | L37: 170.23333
B38: Story | C38: 29405 | D38: 4950 | E38: 3223 | K38: StyleWithMyntra | L38: 141.22727
B39: Text | C39: 31963 | D39: 4792 | E39: 3377 | K39: Grand Total | L39: 151.22
B40: Video | C40: 28947 | D40: 3171 | E40: 2263
B41: Instagram | C41: 204284 | D41: 41444 | E41: 17851
B42: Carousel | C42: 43948 | D42: 6975 | E42: 3890
B43: Image | C43: 34202 | D43: 5286 | E43: 2655
B44: Reel | C44: 32148 | D44: 8110 | E44: 3386
B45: Story | C45: 42649 | D45: 10049 | E45: 3846
B46: Text | C46: 25567 | D46: 5112 | E46: 1946
B47: Video | C47: 25770 | D47: 5912 | E47: 2128
B48: Twitter | C48: 201397 | D48: 33728 | E48: 20880
B49: Carousel | C49: 48649 | D49: 5791 | E49: 3607
B50: Image | C50: 43761 | D50: 7110 | E50: 5125
B51: Reel | C51: 27029 | D51: 4550 | E51: 1913
... B62: Grand Total | C62: 819991 | D62: 142925 | E62: 74851
...

Sheet Task 3
A3: Row Labels | B3: Max of Engagement Rate | C3: Task 3.1 Identify the platform with highest engagement
A4: Facebook | B4: 0.38274707
A5: Instagram | B5: 1.8129252 | E5: Instagram is the platform with highest engagement
A6: Twitter | B6: 0.71686747
A7: YouTube | B7: 0.50192308
A8: Grand Total | B8: 1.8129252
A11: Task 3.2 Compare follower growth rates across platforms
A13: Row Labels | B13: Average of Growth Rate
A14: Facebook | B14: 0.0054649907
A15: Instagram | B15: 0.0057625321
A16: Twitter | B16: 0.0092800257 | E16: Twitter has the highest follower growth rate
A17: YouTube | B17: 0.0090210666
A18: Grand Total | B18: 0.0073821538
A30: Task 2.3 Visualize Engagement vs. Ad Spend per platform.
A32: Row Labels | B32: Average of Engagement_Rate | C32: Average of Ad_Spend
A33: Facebook | B33: 5.6486 | C33: 27590.78
A34: Instagram | B34: 5.7156 | C34: 23287.46
A35: Twitter | B35: 5.6558 | C35: 21207.14
A36: YouTube | B36: 5.5588 | C36: 24572.94
A37: Grand Total | B37: 5.6447 | C37: 24164.58
B43: Instagram has the highest engagement vs Ads spend
A46: Reach per Platform | D46: Advice
A48: Row Labels | B48: Sum of Reach
A49: Facebook | B49: 0.3119035
A50: Instagram | B50: 0.22327631
A51: Twitter | B51: 0.24617864
A52: YouTube | B52: 0.21864156
A53: Grand Total | B53: 1

Sheet Task 4 
A3: Row Labels | B3: Count of Combined Hashtags
A4: FashionDeals | B4: 25
A5: FashionDeals,MyntraFashion | B5: 5 | C5: Task 4.1 Identify most frequently used Myntra hashtags.
A6: FashionDeals,MyntraSale | B6: 4
A7: FashionDeals,MyntraTrend | B7: 8
A8: FashionDeals,StyleWithMyntra | B8: 8
A9: MyntraFashion | B9: 22
A10: MyntraFashion,FashionDeals | B10: 10
A11: MyntraFashion,MyntraSale | B11: 9
A12: MyntraFashion,MyntraTrend | B12: 6
A13: MyntraFashion,StyleWithMyntra | B13: 8
A14: MyntraSale | B14: 32
A15: MyntraSale,FashionDeals | B15: 4
A16: MyntraSale,MyntraFashion | B16: 11
A17: MyntraSale,MyntraTrend | B17: 8
... A23: MyntraTrend,StyleWithMyntra | B23: 8
A24: StyleWithMyntra | B24: 34 | D24: Most Frequent Used Hashtag is Stlye with Myntra
A25: StyleWithMyntra,FashionDeals | B25: 12
A26: StyleWithMyntra,MyntraFashion | B26: 3
A27: StyleWithMyntra,MyntraSale | B27: 7
A28: StyleWithMyntra,MyntraTrend | B28: 10
A29: Grand Total | B29: 300
A33: Row Labels | B33: Average of Clicks
A34: FashionDeals | B34: 155.88
A35: FashionDeals,MyntraFashion | B35: 88.8 | D35: Task 4.2 Compare average performance of posts containing each hashtag.
A36: FashionDeals,MyntraSale | B36: 137.75
A37: FashionDeals,MyntraTrend | B37: 200.625
A38: FashionDeals,StyleWithMyntra | B38: 186.375
A39: MyntraFashion | B39: 146.31818
A40: MyntraFashion,FashionDeals | B40: 112.6
A41: MyntraFashion,MyntraSale | B41: 118.88889
A42: MyntraFashion,MyntraTrend | B42: 207.5
A43: MyntraFashion,StyleWithMyntra | B43: 139.25
A44: MyntraSale | B44: 152.375
A45: MyntraSale,FashionDeals | B45: 142
A46: MyntraSale,MyntraFashion | B46: 126.81818
A47: MyntraSale,MyntraTrend | B47: 145.5
... A55: StyleWithMyntra,FashionDeals | B55: 150.58333
A56: StyleWithMyntra,MyntraFashion | B56: 254.33333 | D56: Post using this hashtag is the highest performing
A57: StyleWithMyntra,MyntraSale | B57: 166
...

Sheet Task 5 
A3: Row Labels | B3: Total of Impressions | C3: Total of Likes | D3: Total of Clicks | F3: Task 5.1 Total Impressions, Likes, Clicks per Campaign.
A4: EndOfSeasonSale | B4: 2886292 | C4: 232785 | D4: 12376
A5: FashionUpgrade | B5: 2788367 | C5: 212431 | D5: 11191
A6: MyntraFestiveEdit | B6: 2611652 | C6: 198666 | D6: 12464
A7: StyleRevolution | B7: 2107842 | C7: 176109 | D7: 9335
A8: Grand Total | B8: 10394153 | C8: 819991 | D8: 45366
A10: Row Labels | B10: Average of Impressions | C10: Average of Clicks | D10: Average of Likes
A11: EndOfSeasonSale | B11: 34774.602 | C11: 149.10843 | D11: 2804.6386 | F11: Task 5.1 Average Impressions, Likes, Clicks per Campaign.
A12: FashionUpgrade | B12: 38727.319 | C12: 155.43056 | D12: 2950.4306
A13: MyntraFestiveEdit | B13: 33482.718 | C13: 159.79487 | D13: 2547
A14: StyleRevolution | B14: 31460.328 | C14: 139.32836 | D14: 2628.4925
A15: Grand Total | B15: 34647.177 | C15: 151.22 | D15: 2733.3033
A20: Row Labels | B20: Average of Engagement Rate | C20: Sum of Likes | D20: Sum of Clicks | E20: Sum of Impressions | F20: Task 5.2 Engagement uplift during vs. before campaigns (e.gFashionUpgrade).
A21: EndOfSeasonSale | B21: 0.15353197 | C21: 232785 | D21: 12376 | E21: 2886292
A22: Before Campaign | B22: 0.12764137 | C22: 222243 | D22: 11725 | E22: 2773076
A23: During Campaign | B23: 0.55742541 | C23: 10542 | D23: 651 | E23: 113216
A24: FashionUpgrade | B24: 0.13707959 | C24: 212431 | D24: 11191 | E24: 2788367
A25: Before Campaign | B25: 0.14157083 | C25: 192047 | D25: 10258 | E25: 2487102
A26: During Campaign | B26: 0.1011497 | C26: 20384 | D26: 933 | E26: 301265
A27: MyntraFestiveEdit | B27: 0.14444571 | C27: 198666 | D27: 12464 | E27: 2611652
A28: Before Campaign | B28: 0.14169061 | C28: 175204 | D28: 11150 | E28: 2393315
A29: During Campaign | B29: 0.16556814 | C29: 23462 | D29: 1314 | E29: 218337
A30: StyleRevolution | B30: 0.15828608 | C30: 176109 | D30: 9335 | E30: 2107842
A31: Before Campaign | B31: 0.16159866 | C31: 157128 | D31: 8226 | E31: 1890233
A32: During Campaign | B32: 0.13385579 | C32: 18981 | D32: 1109 | E32: 217609
A33: Grand Total | B33: 0.14828272 | C33: 819991 | D33: 45366 | E33: 10394153
A37: Campaingn Name | B37: Enagegment Rate | C37: Uplift
A38: EndOfSeasonSale | B38: 0.15353197 | C38: =(B39-Table4[[#This Row],[Enagegment Rate ]]) -> -0.025890605
A39: Before Campaign | B39: 0.12764137 | C39: =(B40-Table4[[#This Row],[Enagegment Rate ]]) -> 0.42978404
A40: During Campaign | B40: 0.55742541 | C40: =(B41-Table4[[#This Row],[Enagegment Rate ]]) -> -0.42034582
A41: FashionUpgrade | B41: 0.13707959 | C41: =(B42-Table4[[#This Row],[Enagegment Rate ]]) -> 0.0044912364 | E41: Fashion Upgrade Campaign had the highest Upliftment
A42: Before Campaign | B42: 0.14157083 | C42: =(B43-Table4[[#This Row],[Enagegment Rate ]]) -> -0.040421128
A43: During Campaign | B43: 0.1011497 | C43: =(B44-Table4[[#This Row],[Enagegment Rate ]]) -> 0.04329601
A44: MyntraFestiveEdit | B44: 0.14444571 | C44: =(B45-Table4[[#This Row],[Enagegment Rate ]]) -> -0.0027550991
A45: Before Campaign | B45: 0.14169061 | C45: =(B46-Table4[[#This Row],[Enagegment Rate ]]) -> 0.023877525
A46: During Campaign | B46: 0.16556814 | C46: =(B47-Table4[[#This Row],[Enagegment Rate ]]) -> -0.0072820618
A47: StyleRevolution | B47: 0.15828608 | C47: =(B48-Table4[[#This Row],[Enagegment Rate ]]) -> 0.003312582
A48: Before Campaign | B48: 0.16159866 | C48: =(B49-Table4[[#This Row],[Enagegment Rate ]]) -> -0.027742875
A49: During Campaign | B49: 0.13385579 | C49: =(#REF!-Table4[[#This Row],[Enagegment Rate ]]) -> #REF!
A52: Row Labels | B52: Sum of Likes | C52: Sum of Shares | D52: Sum of Comments | E52: Sum of Sum Engagement | F52: Total Bidget | G52: ROI
...

Sheet Task 6
A3: Average of Growth Rate | B3: Column Labels | N3: Task 6.1 Visualize weekly follower growth per platform
A4: Row Labels | B4: Facebook | C4: Instagram | D4: Twitter | E4: YouTube
A5: 2024 | B5: 0.0067042942 | C5: 0.0071795243 | D5: 0.0065260558 | E5: 0.0063525785
A6: Qtr2 | B6: 0.024802029 | C6: 0.0082878238 | D6: 0.0042267778 | E6: 0.0014372646
A7: Qtr3 | B7: 0.0013317581 | C7: 0.0070629862 | D7: 0.0039458377 | E7: 0.0055514286
A8: Qtr4 | B8: 0.0069215686 | C8: 0.0069640115 | D8: 0.010012222 | E8: 0.0087277597
A9: 2025 | B9: 0.0034429691 | C9: 0.0034505976 | D9: 0.013773345 | E9: 0.013374916
A10: Qtr1 | B10: 0.0039035137 | C10: 0.0034672382 | D10: 0.01687406 | E10: 0.014580089
A11: Qtr2 | B11: 0.0024451225 | C11: 0.003414543 | D11: 0.0070551288 | E11: 0.010763707
M25: Task 6.4 Correlate ad spend vs. follower growth using scatter plots.
A27: Row Labels | B27: Average of Ad_Spend | C27: Average of Growth Rate
A28: Facebook | B28: 27590.78 | C28: 0.0054649907
A29: Instagram | B29: 23287.46 | C29: 0.0057625321
A30: Twitter | B30: 21207.14 | C30: 0.0092800257
A31: YouTube | B31: 24572.94 | C31: 0.0090210666
A43: Row Labels | B43: Sum of New_Followers
A44: 45656 | B44: 7075 | D44: Task 6.2 Identify the peak week of follower gain.
A45: 45600 | B45: 5741
A46: 45621 | B46: 5187
A47: 45607 | B47: 3187
A48: 45614 | B48: 1606

Sheet Engagment Summary
A1: Week_Start_Date | B1: Platform | C1: New_Followers | D1: Unfollows | E1: Total_Followers | F1: Engagement_Rate | G1: Ad_Spend | H1: Growth Rate | I1: Growth Rate 2 | J1: Campaign_Name
A2: 45446 | B2: Instagram | C2: 1135 | D2: 88 | E2: 344084 | F2: 8.06 | G2: 5904 | H2: =(Engagment_Summary[[#This Row],[New_Followers]]-Engagment_Summary[[#This Row],[Unfollows]]) /Engagment_Summary[[#This Row],[Total_Followers]] -> 0.0030428616 | I2: =(Engagment_Summary[[#This Row],[New_Followers]]-Engagment_Summary[[#This Row],[Unfollows]]/Engagment_Summary[[#This Row],[Total_Followers]]) -> 1134.9997 | J2: EndOfSeasonSale
A3: 45446 | B3: Facebook | C3: 1312 | D3: 310 | E3: 42654 | F3: 4.98 | G3: 9566 | H3: =(Engagment_Summary[[#This Row],[New_Followers]]-Engagment_Summary[[#This Row],[Unfollows]]) /Engagment_Summary[[#This Row],[Total_Followers]] -> 0.023491349 | I3: =(Engagment_Summary[[#This Row],[New_Followers]]-Engagment_Summary[[#This Row],[Unfollows]]/Engagment_Summary[[#This Row],[Total_Followers]]) -> 1311.9927 | J3: FashionUpgrade
A4: 45446 | B4: Twitter | C4: 584 | D4: 169 | E4: 146834 | F4: 8.31 | G4: 26752 | H4: =(Engagment_Summary[[#This Row],[New_Followers]]-Engagment_Summary[[#This Row],[Unfollows]]) /Engagment_Summary[[#This Row],[Total_Followers]] -> 0.0028263209 | I4: =(Engagment_Summary[[#This Row],[New_Followers]]-Engagment_Summary[[#This Row],[Unfollows]]/Engagment_Summary[[#This Row],[Total_Followers]]) -> 583.99885 | J4: MyntraFestiveEdit
A5: 45446 | B5: YouTube | C5: 1535 | D5: 445 | E5: 395536 | F5: 4.11 | G5: 30671 | H5: =(Engagment_Summary[[#This Row],[New_Followers]]-Engagment_Summary[[#This Row],[Unfollows]]) /Engagment_Summary[[#This Row],[Total_Followers]] -> 0.0027557542 | I5: =(Engagment_Summary[[#This Row],[New_Followers]]-Engagment_Summary[[#This Row],[Unfollows]]/Engagment_Summary[[#This Row],[Total_Followers]]) -> 1534.9989 | J5: StyleRevolution
A6: 45453 | B6: Instagram | C6: 656 | D6: 139 | E6: 49157 | F6: 9.05 | G6: 9920 | H6: =(Engagment_Summary[[#This Row],[New_Followers]]-Engagment_Summary[[#This Row],[Unfollows]]) /Engagment_Summary[[#This Row],[Total_Followers]] -> 0.010517322 | I6: =(Engagment_Summary[[#This Row],[New_Followers]]-Engagment_Summary[[#This Row],[Unfollows]]/Engagment_Summary[[#This Row],[Total_Followers]]) -> 655.99717
A7: 45453 | B7: Facebook | C7: 1697 | D7: 414 | E7: 316555 | F7: 2.37 | G7: 7924 | H7: =(Engagment_Summary[[#This Row],[New_Followers]]-Engagment_Summary[[#This Row],[Unfollows]]) /Engagment_Summary[[#This Row],[Total_Followers]] -> 0.0040530082 | I7: =(Engagment_Summary[[#This Row],[New_Followers]]-Engagment_Summary[[#This Row],[Unfollows]]/Engagment_Summary[[#This Row],[Total_Followers]]) -> 1696.9987
A8: 45453 | B8: Twitter | C8: 436 | D8: 250 | E8: 254347 | F8: 4.01 | G8: 8912 | H8: =(Engagment_Summary[[#This Row],[New_Followers]]-Engagment_Summary[[#This Row],[Unfollows]]) /Engagment_Summary[[#This Row],[Total_Followers]] -> 0.00073128443 | I8: =(Engagment_Summary[[#This Row],[New_Followers]]-Engagment_Summary[[#This Row],[Unfollows]]/Engagment_Summary[[#This Row],[Total_Followers]]) -> 435.99902
A9: 45453 | B9: YouTube | C9: 1197 | D9: 203 | E9: 413878 | F9: 3.16 | G9: 21205 | H9: =(Engagment_Summary[[#This Row],[New_Followers]]-Engagment_Summary[[#This Row],[Unfollows]]) /Engagment_Summary[[#This Row],[Total_Followers]] -> 0.0024016739 | I9: =(Engagment_Summary[[#This Row],[New_Followers]]-Engagment_Summary[[#This Row],[Unfollows]]/Engagment_Summary[[#This Row],[Total_Followers]]) -> 1196.9995
A10: 45460 | B10: Instagram | C10: 1048 | D10: 155 | E10: 456946 | F10: 2.46 | G10: 11329 | H10: =(Engagment_Summary[[#This Row],[New_Followers]]-Engagment_Summary[[#This Row],[Unfollows]]) /Engagment_Summary[[#This Row],[Total_Followers]] -> 0.0019542791 | I10: =(Engagment_Summary[[#This Row],[New_Followers]]-Engagment_Summary[[#This Row],[Unfollows]]/Engagment_Summary[[#This Row],[Total_Followers]]) -> 1047.9997
A11: 45460 | B11: Facebook | C11: 1753 | D11: 371 | E11: 169496 | F11: 8.11 | G11: 46670 | H11: =(Engagment_Summary[[#This Row],[New_Followers]]-Engagment_Summary[[#This Row],[Unfollows]]) /Engagment_Summary[[#This Row],[Total_Followers]] -> 0.0081535847 | I11: =(Engagment_Summary[[#This Row],[New_Followers]]-Engagment_Summary[[#This Row],[Unfollows]]/Engagment_Summary[[#This Row],[Total_Followers]]) -> 1752.9978
A12: 45460 | B12: Twitter | C12: 1335 | D12: 40 | E12: 122732 | F12: 8.19 | G12: 22482 | H12: =(Engagment_Summary[[#This Row],[New_Followers]]-Engagment_Summary[[#This Row],[Unfollows]]) /Engagment_Summary[[#This Row],[Total_Followers]] -> 0.010551445 | I12: =(Engagment_Summary[[#This Row],[New_Followers]]-Engagment_Summary[[#This Row],[Unfollows]]/Engagment_Summary[[#This Row],[Total_Followers]]) -> 1334.9997
A13: 45460 | B13: YouTube | C13: 403 | D13: 66 | E13: 382851 | F13: 3.49 | G13: 24313 | H13: =(Engagment_Summary[[#This Row],[New_Followers]]-Engagment_Summary[[#This Row],[Unfollows]]) /Engagment_Summary[[#This Row],[Total_Followers]] -> 0.000880238 | I13: =(Engagment_Summary[[#This Row],[New_Followers]]-Engagment_Summary[[#This Row],[Unfollows]]/Engagment_Summary[[#This Row],[Total_Followers]]) -> 402.99983
A14: 45467 | B14: Instagram | C14: 911 | D14: 282 | E14: 35664 | F14: 6.92 | G14: 18050 | H14: =(Engagment_Summary[[#This Row],[New_Followers]]-Engagment_Summary[[#This Row],[Unfollows]]) /Engagment_Summary[[#This Row],[Total_Followers]] -> 0.017636833 | I14: =(Engagment_Summary[[#This Row],[New_Followers]]-Engagment_Summary[[#This Row],[Unfollows]]/Engagment_Summary[[#This Row],[Total_Followers]]) -> 910.99209
A15: 45467 | B15: Facebook | C15: 1779 | D15: 109 | E15: 26295 | F15: 9.12 | G15: 30635 | H15: =(Engagment_Summary[[#This Row],[New_Followers]]-Engagment_Summary[[#This Row],[Unfollows]]) /Engagment_Summary[[#This Row],[Total_Followers]] -> 0.063510173 | I15: =(Engagment_Summary[[#This Row],[New_Followers]]-Engagment_Summary[[#This Row],[Unfollows]]/Engagment_Summary[[#This Row],[Total_Followers]]) -> 1778.9959
A16: 45467 | B16: Twitter | C16: 1238 | D16: 403 | E16: 298421 | F16: 3.5 | G16: 31280 | H16: =(Engagment_Summary[[#This Row],[New_Followers]]-Engagment_Summary[[#This Row],[Unfollows]]) /Engagment_Summary[[#This Row],[Total_Followers]] -> 0.0027980605 | I16: =(Engagment_Summary[[#This Row],[New_Followers]]-Engagment_Summary[[#This Row],[Unfollows]]/Engagment_Summary[[#This Row],[Total_Followers]]) -> 1237.9986
A17: 45467 | B17: YouTube | C17: 308 | D17: 431 | E17: 426184 | F17: 2.62 | G17: 1783 | H17: =(Engagment_Summary[[#This Row],[New_Followers]]-Engagment_Summary[[#This Row],[Unfollows]]) /Engagment_Summary[[#This Row],[Total_Followers]] -> -0.00028860774 | I17: =(Engagment_Summary[[#This Row],[New_Followers]]-Engagment_Summary[[#This Row],[Unfollows]]/Engagment_Summary[[#This Row],[Total_Followers]]) -> 307.99899
... A201: 45789 | B201: YouTube | C201: 119 | D201: 456 | E201: 82558 | F201: 6.81 | G201: 12174 | H201: =(Engagment_Summary[[#This Row],[New_Followers]]-Engagment_Summary[[#This Row],[Unfollows]]) /Engagment_Summary[[#This Row],[Total_Followers]] -> -0.0040819787 | I201: =(Engagment_Summary[[#This Row],[New_Followers]]-Engagment_Summary[[#This Row],[Unfollows]]/Engagment_Summary[[#This Row],[Total_Followers]]) -> 118.99448

Sheet Campaign Data
A1: Campaign_Name | B1: Start_Date | C1: End_Date | D1: Objective | E1: Total_Budget | F1: Target_Platforms
A2: EndOfSeasonSale | B2: 45453 | C2: 45478 | D2: Seasonal Clearance Promotion | E2: 180000 | F2: Instagram,Facebook
A3: FashionUpgrade | B3: 45505 | C3: 45535 | D3: Customer Engagement | E3: 160000 | F3: Instagram,YouTube
A4: MyntraFestiveEdit | B4: 45570 | C4: 45601 | D4: Festive Collection Launch | E4: 220000 | F4: Facebook,Instagram
A5: StyleRevolution | B5: 45667 | C5: 45698 | D5: Brand Awareness & Growth | E5: 200000 | F5: Instagram,Twitter
